Workbook
Name 返回首页: #REF!
Name 返回首页: 基本平台配置表!$B$1

Sheet 首页
B1: 公司电脑平板产品功能&兼容测试报告
B5: 统一编号： | C5: TFPC/PVC-N-53-R01 | F5: 版本： V1.1 | H5: 标识：*
B6: 功能测试报告
B8: 测试内容
B9: 测试人员 | F9: 测试类型 | G9: □新品□变更
B10: 审核 | F10: 批准
B11: 开始日期 | F11: 结束日期
B14: 序号 | C14: 测试项目 | F14: 测试结果 | I14: 备注
B15: 1 | C15: Stress
B16: 2 | C16: IO Port | D16: IO Port | E16: IO Port
B17: 3 | C17: HW Button | D17: HW Button | E17: HW Button
B18: 4 | C18: Panel | D18: Panel | E18: Panel
B19: 5 | C19: LED | D19: LED | E19: LED
B20: 6 | C20: Camera | D20: Camera | E20: Camera
B21: 7 | C21: GPS | D21: GPS | E21: GPS
B22: 8 | C22: LTE | D22: LTE | E22: LTE
B23: 9 | C23: WIFI | D23: WIFI | E23: WIFI
B24: 10 | C24: SIM | D24: SIM | E24: SIM
B25: 11 | C25: Buletooth | D25: Buletooth | E25: Buletooth
B26: 12 | C26: Sensors | D26: Sensors | E26: Sensors
B27: 13 | C27: SW setting | D27: SW setting | E27: SW setting
... B30: 16 | C30: Software | D30: Software | E30: Software
B31: 测试结论：
B34: 版本 | D34: 日期 | G34: 变更内容
B35: V1.1 | D35: 44070 | G35: 全新改版
B36: V1.2 | D36: 45616 | G36: 更改公司名称

Sheet 基本平台配置表
A1: 基本平台配置表
A2: 部件名称 | B2: 物料编码 | C2: 型号 | D2: 备注
A3: CPU
A4: 主板
A5: 内存
A6: EMMC
A7: 电容笔
A8: 操作系统 | B8: 主测系统
B9: 其他系统
A12: 软件

Sheet Test plan
B2: Test Plan Template
B3: Tester：
B4: 产品类型：
B5: Project Stage：
B6: NO. | C6: Description | D6: Pass/Fail | E6: Comment | F6: Percentage
B7: DVT_001 | C7: Stress | F7: =Stress!F10 -> 0
B8: DVT_002 | C8: IO Port | F8: ='IO Port'!F55 -> 0
B9: DVT_003 | C9: HW Button | F9: ='HW Button'!F35 -> 0
B10: DVT_004 | C10: Panel | F10: =[1]测试记录!H30 -> 0
B11: DVT_005 | C11: LED | F11: =LED!F17 -> 0
B12: DVT_006 | C12: Camera | F12: =Camera!F30 -> 0
B13: DVT_007 | C13: GPS | F13: =GPS!F6 -> 0
B14: DVT_008 | C14: LTE | F14: =LTE!F38 -> 0
B15: DVT_009 | C15: WIFI | F15: =WIFI!F22 -> 0
B16: DVT_010 | C16: SIM | F16: =SIM!F20 -> 0
B17: DVT_011 | C17: Buletooth | F17: =Bluetooth!F49 -> 0
B18: DVT_012 | C18: Sensors | F18: =Sensors!F27 -> 0
B19: DVT_013 | C19: SW setting | F19: ='SW setting'!F99 -> 0
B20: DVT_014 | C20: Peripheral | F20: =Peripheral!F19 -> 0
B21: DVT_015 | C21: Battery life | F21: =BatteryLife!F26 -> 0
B22: DVT_016 | C22: Software | F22: =Software!F6 -> 0

Sheet Stress
B1: NO. | C1: 测试项目 | D1: 判断标准 | E1: 结果 | F1: 备注
B2: 1.Stress
B3: 1.1 | C3: 休眠500cycles | D3: 系统无异常，各功能正常；不能出现画面模糊，闪屏黑屏等现象
B4: 1.2 | C4: 重启500cycles | D4: 系统无异常，各功能正常；不能出现画面模糊，闪屏黑屏等现象
B5: 1.3 | C5: 播放本地视频12hours | D5: 系统无异常，各功能正常；不能出现画面模糊，闪屏黑屏等现象
B6: 1.4 | C6: 播放在线视频12hours | D6: 系统无异常，各功能正常；不能出现画面模糊，闪屏黑屏等现象
B7: 2.ACPI
B8: 2.1 | C8: 手动进入休眠并唤醒 | D8: 系统无异常，各功能正常；不能出现画面模糊，闪屏黑屏等现象
B9: 2.2 | C9: 手动重启平板 | D9: 系统无异常，各功能正常；不能出现画面模糊，闪屏黑屏等现象
F10: =COUNTA(E3:E6,E8:E9)/COUNTA(D3:D6,D8:D9) -> 0

Sheet IO Port
B1: NO. | C1: 测试项目 | D1: 判断标准 | E1: 结果 | F1: 备注
B2: 1.Internal Speaker/Microphone/Camera
B3: 1.1 | C3: Internal Speaker: 播放MP3,确认内建喇叭的左右声道音量是否平均 | D3: 内建喇叭左右声道音量正常
B4: 1.2 | C4: Internal Speaker: 播放音乐过程中,反复插拔外接式耳机3次 | D4: 1.插入耳机->音乐切换到外接耳机 2.拔出耳机->音乐切换到内建喇吧 3.系统不可出现异常
B5: 1.3 | C5: Internal Speaker: 播放音乐后暂停播放,平板进入休眠后及唤醒 | D5: 休眠与唤醒过程,内建喇叭不可有明显异音
B6: 1.4 | C6: Internal Speaker: 插AC充电中,平板关机、开机、运作中静置 | D6: 关机与开机过程、静置时,内建喇叭不可有明显异音
B7: 1.5 | C7: Internal Speaker: 移除AC电源,平板关机、开机、运作中静置 | D7: 关机与开机过程、静置时,内建喇叭不可有明显异音
B8: 1.6 | C8: Microphone录音大小(外部播放): 1.在35dB以下环境(静音室) 2.平板的麦克风与人距离35cm 3.使用平板内置录音apk录音 4.平板录下来的声音公放 | D8: 在内置speaker声音调至50%时，安静环境下播放所录音屏内容清晰无特殊杂音；声音调至100%时，工作环境（有杂音）可明显播放内容
B9: 1.7 | C9: Front Camera:开启Camera程序,使用前镜头拍照和录像 | D9: 预览画面为镜射,拍照和录像的方向、颜色、声音皆正常
B10: 1.8 | C10: Rear Camera:开启Camera程序,使用后镜头拍照和录像 | D10: 拍照和录像的方向、颜色、声音皆正常
B11: 2.External Headphone & Microphone
B12: 2.1 | C12: 插入外接耳机(3段式与4段式(非nokia),播放音视频 | D12: 外接耳机左右声道音量平均、无杂音
B13: 2.2 | C13: 播放音视频，插入外接耳机(3段式与4段式(非nokia) | D13: 音源输出切换到外界耳机，外接耳机左右声道音量平均、无杂音
B14: 2.3 | C14: 插入外接耳机，播放音乐后暂停播放,平板进入休眠后唤醒 | D14: 休眠与唤醒过程,外接耳机不可有明显异音
B15: 2.4 | C15: 插AC充电中，插入外接耳机，平板关机、开机、运作中静置调整音量0~100% | D15: 关机与开机过程、静置调整音量时,外接耳机不可有明显异音
B16: 2.5 | C16: 移除AC电源,插入外接耳机,平板关机、开机、运作中静置调整音量0~100% | D16: 关机与开机过程、静置调整音量时,外接耳机不可有明显异音
B17: 2.6 | C17: 4段式耳麦座-外接式麦克风: 1.插入4段式(非nokia)耳麦 2.进行录音 | D17: 1.外接式麦克风可以录音，内置麦克风无法录音 2.播放录音，清晰无异常杂音
B18: 2.7 | C18: 4段式耳麦座-插3段式耳机: 1.插入3段式耳机 2.进行录音 | D18: 内置麦克风仍然可以录音
B19: 2.8 | C19: 插入外接耳机 | D19: 2秒内，设备状态栏显示耳机图标；移除外接耳机，2秒内，设备状态栏的耳机图标消失
B20: 3.Host mode USB Port(平板自带USB/Type-C口支持HOST MODE则测试，不支持请打NS)
B21: 3.1 | C21: 1.依据spec.文件,确认Host mode的USB port位置,并确认是否要从APK程序或从Settings/Developer options做切换成Host mode的动作. 2.使用出货USB转接线材,插入USB键盘,在桌面按任意按键(包含数字键区) | D21: 插入USB键盘后功能正常使用 (在桌面按USB键盘后, 会自动跳到Search程序)
B22: 3.2 | C22: 1.依据spec.文件,确认Host mode的USB port位置,并确认是否要从APK程序或从Settings/Developer options做切换成Host mode的动作. 2.使用出货USB转接线材,插入并操作USB鼠标 | D22: 插入USB鼠标后功能正常使用(有显示鼠标，可点选/滑动正常)
B23: 3.3 | C23: 1.依据spec.文件,确认Host mode的USB port位置,并确认是否要从APK程序或从Settings/Developer options做切换成Host mode的动作. 2.使用出货USB转接线材,插入并操作USB鼠标/键盘,进休眠1分钟后,操作USB鼠标/键盘 | D23: 操作USB鼠标/键盘后不可以唤醒
B24: 3.4 | C24: 1.依据spec.文件,确认Host mode的USB port位置,并确认是否要从APK程序或从Settings/Developer options做切换成Host mode的动作. 2.使用出货USB转接线材,插入USB Flash Disk后,以档案总管软件做档案读取及写入 | D24: 插入USB Flash Disk后功能正常使用
B25: 3.5 | C25: 1.依据spec.文件,确认Host mode的USB port位置,并确认是否要从APK程序或从Settings/Developer options做切换成Host mode的动作. 2.使用出货USB转接线材,插入USB HDD(无外接电源)后,做文件读取及写入 | D25: 插入USB HDD后功能正常使用(可大量复制数据)
B26: 3.6 | C26: U盘里存有大于2G的文件 用OTG线接U盘及平板，U盘向平板传输大于2G的文件存于根目录 | D26: 可成功将文件传入平板
B27: 3.7 | C27: 平板里存有大于2G的文件 用OTG线连接U盘及平板，平板向U盘传输大于2G的文件存于根目录 | D27: 可成功将文件传入U盘
B28: 4.Device mode USB Port（包含Type-A\C)
B29: 4.1 | C29: 1.依据spec.文件,确认Device mode的USB port位置,并确认是否要从APK程序或从Settings/Developer options做切换成Device mode的动作. 2.使用出货USB转接线材,平板运作中时连接计算机,使用计算机读写平板计算机的外部Micro SD卡和内部SD card | D29: 计算机端可擦写平版外部Micro SD卡和内部SD card的档案
B30: 4.2 | C30: 1、用USB线连接平板与电脑>打开“USB存储设备”>从电脑复制大于1G文件并贴粘到平板内置存储根目录 2、用USB线连接平板与电脑>打开“USB存储设备”>从电脑复制小于1G文件并贴粘到平板内置存储根目录 | D30: 大于1G和小于1G的文件都可以传输完成，并能在平板内查看该文件
B31: 4.3 | C31: 平板接入一张大于2G SD卡 1、用USB线连接平板与电脑>打开“USB存储设备”>从电脑复制大于1G文件并贴粘到平板外部Micro SD卡存储根目录 2、用USB线连接平板与电脑>打开“USB存储设备”>从电脑复制小于1G文件并贴粘到平板外部Micro SD卡存储根目录 | D31: 大于1G和小于1G的文件都可以传输完成，并能在平板内查看该文件
B32: 5.Device mode USB Charge Port (PC charge function by Spec. definition)
B33: 5.1 | C33: 1.依据spec.文件,确认Device mode的USB port是否有连接PC计算机充电功能. 2.依据spec.文件,确认Device mode的USB port位置,并确认是否要从APK程序或从Settings/Developer options做切换成Device mode的动作. 3.使用出货USB转接线材,平板运作中时连接计算机 | D33: 平板接上计算机1秒内有出现充电符号(依SPEC而定)
B34: 5.2 | C34: 1.依据spec.文件,确认Device mode的USB port是否有连接PC计算机充电功能. 2.依据spec.文件,确认Device mode的USB port位置,并确认是否要从APK程序或从Settings/Developer options做切换成Device mode的动作. 3.WiFi/BT/TLE都关闭,使用出货USB转接线材,平板运作时连接计算机,不操作平版&不可进休眠(等候约30分钟)，亮度调节为100%，记录电量变化。 4，WiFi/BT/TLE都关闭,仅使用电池模式，不操作平版&不可进休眠(等候约30分钟)，亮度调节为100%，记录电量变化 | D34: 连接电脑时掉电不可以比battery模式下掉电更快。
B35: 5.3 | C35: 1.依据spec.文件,确认Device mode的USB port是否有连接PC计算机充电功能. 2.依据spec.文件,确认Device mode的USB port位置,并确认是否要从APK程序或从Settings/Developer options做切换动作. 3.使用出货USB转接线材,平板休眠时连接计算机 | D35: 平板接上计算机1秒内有出现LED充电灯号
B36: 5.4 | C36: 1.依据spec.文件,确认Device mode的USB port是否有连接PC计算机充电功能. 2.依据spec.文件,确认Device mode的USB port位置,并确认是否要从APK程序或从Settings/Developer options做切换动作. 3.使用出货USB转接线材,平板休眠时连接计算机(等候约10分钟) | D36: 充电一段时间后，看电量是否有增加
B37: 6.OTG mode USB Port
B38: 6.1 | C38: 1.依据spec.文件,确认具有OTG mode的USB port位置,然后插入OTG的USB转换线. 2.使用出货OTG USB转接线材,插入并操作USB鼠标 | D38: 1.插入OTG USB转接线材后会变成Host模式,USB鼠标能正常使用(有显示鼠标，可点选/滑动正常) 2.Settings\Developer options\Usb switch mode, 不管是设为Host mode或Device mode, 都不影响OTG USB线的功能,i.e,插入OTG USB转换线后一定都是Host功能
B39: 6.2 | C39: 1.依据spec.文件,确认具有OTG mode的USB port位置,然后插入OTG的USB转换线. 2.使用出货OTG USB转接线材,插入USB转RJ45设备，再插入网线 3，将机台本身WIFI由ON调为OFF 4，打开Setting-more-ethernet,勾选Use ethernet | D39: 1，右下角要出现2个小电脑图标 2，要看到Ip address正确，mac address正确。 3，打开浏览器，要求能正常访问网页。
B40: 7.Charge Port(充电埠, Defined by spec. )
...

Sheet HW Button
B1: NO. | C1: 测试项目 | D1: 判断标准 | E1: 结果 | F1: 备注
B2: 1. Power Button
B3: 1.1 | C3: 在插入AC模式关机状态下,按下非Power button(Volume Up/Down, Home,Menu,Touch screen)不可以开机 | D3: 按非Power button不可以开机
B4: 1.2 | C4: 在移除AC模式关机状态下,按下非Power button(Volume Up/Down, Home,Menu,Touch screen)不可以开机 | D4: 按非Power button不可以开机
B5: 1.3 | C5: 在插入AC模式关机状态下,按Power button开机,计算到解锁(Screen Lock)画面的开机时间 | D5: 按下1秒(具体按SW spec.)开机可正常进入系统,开机时间 ≤ 60秒
B6: 1.4 | C6: 在移除AC模式关机状态下,按Power button开机,计算到解锁(Screen Lock)画面的开机时间 | D6: 按下1秒(具体按SW spec.)开机可正常进入系统,开机时间 ≤ 60秒
B7: 1.5 | C7: 1.确认机器的预设摆设方向为水平或垂直(通常依印刷的按钮文字方向辨认,或前镜头边为朝上) 2.按Power button开机,直到解锁画面 | D7: 从开机到解锁之间的画面显示方向, 应与机器的预设摆设方向相同
B8: 1.6 | C8: 在插入AC模式系统运作状态中, 按下Power Button进入休眠(Suspend) | D8: 系统可进入休眠模式(Suspend)
B9: 1.7 | C9: 在移除AC模式系统运作状态中, 按下Power Button进入休眠(Suspend) | D9: 系统可进入休眠模式(Suspend)
B10: 1.8 | C10: 在插入AC模式进入休眠三秒后,按下非Power button(Volume Up/Down, Home,Menu,Back,Touch screen…...) | D10: 非Power button无法于休眠状态下唤醒系统
B11: 1.9 | C11: 在移除AC模式进入休眠三秒后,按下非Power button(Volume Up/Down,Home,Menu,Back,Touch screen…...) | D11: 非Power button无法于休眠状态下唤醒系统
B12: 1.10 | C12: 在插入AC模式进入休眠三秒后,按下Power Button从休眠模式(Suspend)中唤醒 | D12: 按下Power Button1秒内要看见解锁画面
B13: 1.11 | C13: 在移除AC模式进入休眠三秒后,按Power Button从休眠模式(Suspend)中唤醒 | D13: 按下Power Button1秒内要看见解锁画面
B14: 1.12 | C14: 在解锁画面,按下非Power button(Volume Up/Down, Home, Menu, Back) | D14: 不可解锁进入系统
... B18: 1.16 | C18: 在移除AC模式,系统运作状态中,按住Power Button X秒 | D18: 系统会强制关机
B19: 2. Volume Up/Down button
B20: 2.1 | C20: 播放音乐,每按下Volume Up Button后 | D20: 跳出音量bar选单并增长bar,音量逐步变大(PS.Android非等比例变大声)
B21: 2.2 | C21: 播放音乐,每按下Volume Down Button后 | D21: 跳出音量bar选单并缩短bar,音量逐步变小(PS.Android非等比例变小声)
B22: 2.3 | C22: 播音乐,按住不放Volume Up Button后 | D22: 跳出音量bar选单并增长bar,音量逐步变大(PS.Android非等比例变大声)
B23: 2.4 | C23: 播音乐,按住不放Volume Down Button后 | D23: 1.跳出音量bar选单并缩短bar,音量逐步变小(PS.Android非等比例变小声) 2.按到底时会切换成静音图示
B24: 3. Home /Back /Menu button
B25: 3.1 | C25: 在系统中,选择进入应用程序(Apps) >设定(Settings) >关于平板计算机(about tablet),然后按下Home Button | D25: 按下Home Button会立即回到桌面上
B26: 3.2 | C26: 在系统中,选择进入应用程序(Apps) >设定(Settings) >关于平板计算机(about tablet),然后按下Back Button会回到上一页面 | D26: 按下Back Button会回到上一页面
B27: 3.3 | C27: 在系统中桌面下,按Menu Button | D27: 按下Menu Button后会出现对应的选单
B28: 3.4 | C28: 当系统从休眠模式唤醒回来后,按下Home/Back/Menu Button | D28: 当系统从休眠模式唤醒回来后,所有的Button仍可正常动作
B29: 4.开机检查
B30: 4.1 | C30: 插着AC，按power键呼出关机选项，点击Power Off，然后点击OK。进行关机动作 | D30: 可以正常关机，然后还可以开机
B31: 4.2 | C31: 插着AC，长按power键关机（或者按reset关机），进行关机动作 | D31: 可以正常关机，然后还可以开机
B32: 4.3 | C32: USB口插着OTG线，按power键呼出关机选项，点击Power Off，然后点击OK。进行关机动作 | D32: 可以正常关机，然后还可以开机
B33: 4.4 | C33: USB口插着OTG线，长按power键关机（或者按reset关机），进行关机动作 | D33: 可以正常关机，然后还可以开机
B34: 4.5 | C34: 按Power 超过X秒后，再松手。机台不会开机 | D34: 再次按power键X秒，可以开机
F35: =COUNTA(E30:E34,E25:E28,E20:E23,E3:E18)/COUNTA(D3:D18,D20:D23,D25:D28,D30:D34) -> 0

Sheet Panel
B1: NO. | C1: 测试项目 | D1: 判断标准 | E1: 结果 | F1: 备注
B2: 1.LCD Panel
B3: 1.1 | C3: 1.安装并执行"滚球游戏"3D Bio Ball HD FREE 3.6.apk" 2.于室内室外环境测试滚球游戏是否可视角影响游戏操作 | D3: 1.于室内室外环境测试滚球游戏可视角度良好可轻易操作游戏 2.LCD Panel可视角度符合产品规格(Ex.左右角度45~135, 上下角度45~135)
B4: 1.2 | C4: 于室内室外环境播放电影(SummerTime-LCDtest.mp4)由三人同时观看是否能顺利看到画面与字幕 | D4: 于室内室外环境三人同时观看电影可顺利看到画面与字幕
B5: 1.3 | C5: 1.系统在运作状态下 2.反复插拔AC电源 3.观察屏幕画面是否出现异常现象如闪烁/白屏/黑屏 | D5: 插拔AC电源屏幕画面不可出现异常
B6: 1.4 | C6: 1.插AC充电中 2.平板进入休眠后及唤醒平板 3.观察屏幕画面是否出现异常现象如闪烁/白屏/黑屏 | D6: 平板进入休眠及唤醒屏幕画面不可出现异常
B7: 1.5 | C7: 1.移除AC电源 2.平板进入休眠后及唤醒平板 3.观察屏幕画面是否出现异常现象如闪烁/白屏/黑屏 | D7: 平板进入休眠及唤醒屏幕画面不可出现异常
B8: 1.6 | C8: 1.插AC充电中 2.平板正常开机与关机 3.观察屏幕画面是否出现异常现象如闪烁/白屏/黑屏 | D8: 平板开关机过程屏幕画面不可出现异常
B9: 1.7 | C9: 1.移除AC电源 2.平板正常开机与关机 3.观察屏幕画面是否出现异常现象如闪烁/白屏/黑屏 | D9: 平板开关机过程屏幕画面不可出现异常
B10: 1.8 | C10: 安装ITEST.APK，安装完成后打开，选择LCD TEST。 | D10: 观察各种纯颜色图片，颜色无异常。
B11: 2.Touch Panel
B12: 2.1 | C12: 1.插AC充电中 2.安装并执行TouchTest.apk程序 3.单手扶持平版(水平及垂直),单指快速在屏幕上下左右靠近边框大范围滑动 4.平版平放于办公桌桌面(水平及垂直),单指快速在屏幕上下左右靠近边框大范围滑动 | D12: 划出的线条不可中断且必须紧跟着手指不超过2个手指的距离
B13: 2.2 | C13: 1.移除AC电源 2.安装并执行TouchTest.apk程序 3.单手扶持平版(水平及垂直),单指快速在屏幕上下左右靠近边框大范围滑动 4.平版平放于办公桌桌面(水平及垂直),单指快速在屏幕上下左右靠近边框大范围滑动 | D13: 划出的线条不可中断且必须紧跟着手指不超过2个手指的距离
B14: 2.3 | C14: 插AC条件下,屏幕边界灵敏度问题 1.插AC充电中 2.安装并执行TouchTest.apk程序 3.单指在屏幕四周边界内平行滑动 4.单指在屏幕四周边界外平行滑动 5.单指在屏幕四周边界垂直滑动 | D14: 1.屏幕可触碰区与不可触碰区应界线分明 2.可触碰区与屏幕边界距离小于2mm, 画的线条起伏小于2mm 3.不可触碰区与屏幕边界距离都一致小于2mm, 画的直线起伏小于2mm
B15: 2.4 | C15: 移除AC条件下,屏幕边界灵敏度问题 1.移除AC电源 2.安装并执行TouchTest.apk程序 3.单指在屏幕四周边界内平行滑动 4.单指在屏幕四周边界外平行滑动 5.单指在屏幕四周边界垂直滑动 | D15: 1.屏幕可触碰区与不可触碰区应界线分明 2.可触碰区与屏幕边界距离小于2mm, 画的线条起伏小于2mm 3.不可触碰区与屏幕边界距离都一致小于2mm, 画的直线起伏小于2mm
B16: 2.5 | C16: 1.插AC充电中 2.安装并执行"MultiTouch Tester_1.0.apk" 3.将□□指放在屏幕上观察程序显示的数字 (或将□□指逐一平均放在屏幕上) 4.超过□□指放在屏幕上观察程序显示的数字 (或超过□□指逐一平均放在屏幕上) | D16: 1.程序出现的数字符合产品规格的多指触碰 2.超过产品规格的指数,不会出现异常 | F16: 最多可显示十指
B17: 2.6 | C17: 1.移除AC电源 2.安装并执行"MultiTouch Tester_1.0.apk" 3.将□□指放在屏幕上观察程序显示的数字 (或将□□指逐一平均放在屏幕上) 4.超过□□指放在屏幕上观察程序显示的数字 (或超过□□指逐一平均放在屏幕上) | D17: 1.程序出现的数字符合产品规格的多指触碰 2.超过产品规格的指数,不会出现异常 | F17: 最多可显示十指
B18: 2.7 | C18: 1.插AC充电中 2.安装并执行"MultiTouch Tester_1.0.apk" 3.□□指同时在屏幕滑动 4.超过□□指同时在屏幕滑动 | D18: 1.多指同时滑动时,手指下的数字不可变更或消失 2.超过产品规格的指数滑动时,手指下的数字不可变更或消失
B19: 2.8 | C19: 1.移除AC电源 2.安装并执行"MultiTouch Tester_1.0.apk" 3.□□指同时在屏幕滑动 4.超过□□指同时在屏幕滑动 | D19: 1.多指同时滑动时,手指下的数字不可变更或消失 2.超过产品规格的指数滑动时,手指下的数字不可变更或消失
B20: 2.9 | C20: 1.插AC充电中 2.勾选 设定(Settings)/开发人员选项(Developer options)/指针位置(Pointer Location), 或安装Dev Tools APK进行测试 3.使用3指同时画长线(指头间距15mm,几指测试根据产品规格),水平及垂直都要测 | D20: 可同时用3指画长线(直线/波浪)且各长线之间不会互相干扰
B21: 2.10 | C21: 1.移除AC电源 2.勾选 设定(Settings)/开发人员选项(Developer options)/指针位置(Pointer Location), 或安装Dev Tools APK进行测试 3.使用3指同时画长线(指头间距15mm,几指测试根据产品规格),水平及垂直都要测 | D21: 可同时用3指画长线(直线/波浪)且各长线之间不会互相干扰
B22: 2.11 | C22: 1.插AC充电中 2.勾选设定(Settings)/开发人员选项(Developer options)/指针位置(Pointer Location) 3.双指测试是否出现鬼点,参考http://www.youtube.com/watch?v=hVlsRCMltDg,左边的HTC手机有鬼点,右边的Samsung手机无鬼点 | D22: 双指测试没出现鬼点
B23: 2.12 | C23: 1.移除AC电源 2.勾选设定(Settings)/开发人员选项(Developer options)/指针位置(Pointer Location) 3.双指测试是否出现鬼点,参考http://www.youtube.com/watch?v=hVlsRCMltDg,左边的HTC手机有鬼点,右边的Samsung手机无鬼点 | D23: 双指测试没出现鬼点
B24: 2.13 | C24: 到设定(Settings)/应用程序(Apps)/全部(ALL), 在屏幕右边手指小距离(约2cm内)及慢速度滑动,浏览程序列表,水平及垂直都要测 | D24: 手指小距离(约2cm内)及慢速度滑动时,程序列表不会突然移动很多
B25: 2.14 | C25: 插AC条件下,平板边框不可有触碰反应问题 1.插AC充电中 2.勾选设定(Settings)/开发人员选项(Developer options)/指针位置(Pointer Location) 3.双手扶持平版,以大拇指用力按压屏幕不可触碰区(也就是四周边框) | D25: 1.用力按压边框时,屏幕可触碰区不可以有反应 2.手指距离屏幕可触碰区小于2mm
B26: 2.15 | C26: 移除AC条件下,平板边框不可有触碰反应问题 1.移除AC电源 2.勾选设定(Settings)/开发人员选项(Developer options)/指针位置(Pointer Location) 3.双手扶持平版,以大拇指用力按压屏幕不可触碰区(也就是四周边框) | D26: 1.用力按压边框时,屏幕可触碰区不可以有反应 2.手指距离屏幕可触碰区小于2mm
B27: 2.16 | C27: 平板单手持&插AC条件下,单点重压是否有按A处却B处反应问题 1.插AC充电中 2.勾选设定(Settings)/开发人员选项(Developer options)/指针位置(Pointer Location) 3.单手扶持平版,以食指单点击方式,单次用力按压屏幕可触碰区 4.单手扶持平版,以食指单点击方式,长时间用力按住压屏幕可触碰区 | D27: 1.单手扶持:单次用力按压屏幕可触碰区时,屏幕可触碰区应该只有一个点的反应,手指中心位置与反应位置不可超出5mm,不可以出现随机划线的反应 2.单手扶持:长时间用力按住压屏幕可触碰区时,屏幕可触碰区应该只有一个点的反应,手指中心位置与反应位置不可超出5mm,不可以出现随机划线的反应
B28: 2.17 | C28: 平板单手持&移除AC条件下,单点重压是否有按A处却B处反应问题 1.移除AC电源 2.勾选设定(Settings)/开发人员选项(Developer options)/指针位置(Pointer Location) 3.单手扶持平版,以食指单点击方式,单次用力按压屏幕可触碰区 4.单手扶持平版,以食指单点击方式,长时间用力按住压屏幕可触碰区 | D28: 1.单手扶持:单次用力按压屏幕可触碰区时,屏幕可触碰区应该只有一个点的反应,手指中心位置与反应位置不可超出5mm,不可以出现随机划线的反应 2.单手扶持:长时间用力按住压屏幕可触碰区时,屏幕可触碰区应该只有一个点的反应,手指中心位置与反应位置不可超出5mm,不可以出现随机划线的反应
B29: 2.18 | C29: 平板放桌上&插AC条件下,单点重压是否有按A处却B处反应问题 1.插AC充电中 2.勾选设定(Settings)/开发人员选项(Developer options)/指针位置(Pointer Location) 3.平版平放于办公桌桌面,以食指单点击方式,单次用力按压屏幕可触碰区 4.平版平放于办公桌桌面,以食指单点击方式,长时间用力按住压屏幕可触碰区 | D29: 1.平放桌面:单次用力按压屏幕可触碰区时,屏幕可触碰区应该只有一个点的反应,手指中心位置与反应位置不可超出5mm,不可以出现随机划线的反应 2.平放桌面:长时间用力按住压屏幕可触碰区时,屏幕可触碰区应该只有一个点的反应,手指中心位置与反应位置不可超出5mm,不可以出现随机划线的反应
... B33: 2.22 | C33: 不插AC，关闭机台所有任务，将机台放置30分钟，让机台进入S3，然后唤醒 | D33: 检查是否有唤醒后TP无功能的情况
F35: =LED!F17 -> 0

Sheet LED
B1: NO. | C1: 测试项目 | D1: 判断标准 | E1: 结果 | F1: 备注
B2: 1.LED indicator
B3: 1.1 | C3: 移除AC电源,按下Power button x秒开机 | D3: 电源灯不亮
B4: 1.2 | C4: 移除AC电源,系统运作状态中,按下Power button进入休眠 | D4: 电源灯不亮
B5: 1.3 | C5: 移除AC电源,系统休眠中,按下Power button唤醒 | D5: 电源灯不亮
B6: 1.4 | C6: 插入AC时进行Battery充电 | D6: 接上AC，电源灯长亮绿色
B7: 1.5 | C7: 充饱电时full Battery | D7: 接上AC，电源灯长亮绿色
B8: 1.6 | C8: 移除AC电源,系统运作状态中,电量低于10%(MCU Spec)以下时 | D8: 1.灯号颜色:红色 持续闪烁1次1秒(MCU SPEC), 2.Android系统会秀出10%低电量的warning message
B9: 1.7 | C9: 移除AC电源,系统关机状态中,电量低于10%以下时,按下Power button 1秒开机 | D9: 系统可以开机,灯号颜色:红色 闪烁2次
B10: 1.8 | C10: 移除AC电源,系统休眠状态中,电量低于10%以下时,按下Power button 唤醒 | D10: 系统可以唤醒,灯号颜色:红色 闪烁2次
B11: 1.9 | C11: 移除AC电源,系统运作状态中,电量低于x%以下时 | D11: Android系统会秀出6%电量不足的critical message
B12: 1.10 | C12: 移除AC电源,系统运作状态中,电量低于x%以下时 | D12: Android系统会自动关机
B13: 1.11 | C13: 移除AC电源,系统休眠状态中,电量低于x%以下时 | D13: 系统会强制关机
B14: 1.12 | C14: 移除AC电源,系统运作状态中,电量低于x%(MCU Spec)关机后再开机 | D14: 灯号颜色:红色 亮3秒(MCU SPEC), 机器无法开机
B15: 1.13 | C15: 插入AC电源,关机中&电量低于x%(SW Spec),按Power button开机 | D15: 灯号颜色:红色 亮3秒(MCU SPEC), 机器无法开机
F17: =COUNTA(E3:E15)/COUNTA(D3:D15) -> 0

Sheet Camera
B1: NO. | C1: 测试项目 | D1: 判断标准 | E1: 结果 | F1: 备注
B2: 1.前镜头
B3: 1.1 | C3: 于黄光环境下,执行camera程序切到前镜头进行拍照(水平与垂直) | D3: preview画面与拍出来的画面四周无色偏、无噪点、无水波纹、无失真、无太暗或太亮等问题
B4: 1.2 | C4: 于黄光环境下,执行camera程序切到前镜头进行录像(水平与垂直) | D4: preview画面与录像的影片四周无噪点、无色偏、无水波纹、无失真、无太暗或太亮、无画面延迟等问题
B5: 1.3 | C5: 于白光环境下,执行camera程序切到前镜头进行拍照(水平与垂直) | D5: preview画面与拍出来的画面四周无色偏、无噪点、无水波纹、无失真、无太暗或太亮等问题
B6: 1.4 | C6: 于白光环境下,执行camera程序切到前镜头进行录像(水平与垂直) | D6: preview画面与录像的影片四周无噪点、无色偏、无水波纹、无失真、无太暗或太亮、无画面延迟等问题
B7: 1.5 | C7: 于微光环境下,执行camera程序切到前镜头进行拍照(水平与垂直) | D7: preview画面与拍出来的画面四周无色偏、无水波纹、无失真、无太暗或太亮等问题
B8: 1.6 | C8: 于微光环境下,执行camera程序切到前镜头进行录像(水平与垂直) | D8: preview画面与录像的影片四周无色偏、无水波纹、无失真、无太暗或太亮、无画面延迟等问题
B9: 1.7 | C9: 于日光环境下,执行camera程序切到前镜头进行拍照(水平与垂直) | D9: preview画面与拍出来的画面四周无色偏、无噪点、无水波纹、无失真、无太暗或太亮等问题
B10: 1.8 | C10: 于日光环境下,执行camera程序切到前镜头进行录像(水平与垂直) | D10: preview画面与录像的影片四周无噪点、无色偏、无水波纹、无失真、无太暗或太亮、无画面延迟等问题
B11: 1.9 | C11: 开启Camera程序,使用前镜头拍照和录像 | D11: 预览画面为镜射,拍照和录像方向,颜色,声音皆正常
B12: 1.10 | C12: 刷新System Image及恢复原厂设定(Factory data reset)后,第一次执行Camera程序 | D12: 程序预览画面选定的是前镜头
B13: 2.后镜头
B14: 2.1 | C14: 于黄光环境下,执行camera程序切到后镜头进行拍照(水平与垂直) | D14: preview画面与拍出来的画面四周无色偏、无噪点、无水波纹、无失真、无太暗或太亮等问题
B15: 2.2 | C15: 于黄光环境下,执行camera程序切到后镜头进行录像(水平与垂直) | D15: preview画面与录像的影片四周无噪点、无色偏、无水波纹、无失真、无太暗或太亮、无画面延迟等问题
B16: 2.3 | C16: 于白光环境下,执行camera程序切到后镜头进行拍照(水平与垂直) | D16: preview画面与拍出来的画面四周无噪点、无色偏、无水波纹、无失真、无太暗或太亮、无画面延迟等问题
B17: 2.4 | C17: 于白光环境下,执行camera程序切到后镜头进行录像(水平与垂直) | D17: preview画面与录像的影片四周无噪点、无色偏、无水波纹、无失真、无太暗或太亮、无画面延迟等问题
B18: 2.5 | C18: 于微光环境下,执行camera程序切到后镜头进行拍照(水平与垂直) | D18: preview画面与拍出来的画面四周无色偏、无水波纹、无失真、无太暗或太亮、无画面延迟等问题
B19: 2.6 | C19: 于微光环境下,执行camera程序切到后镜头进行录像(水平与垂直) | D19: preview画面与录像的影片四周无色偏、无水波纹、无失真、无太暗或太亮、无画面延迟等问题
B20: 2.7 | C20: 于日光环境下,执行camera程序切到后镜头进行拍照(水平与垂直) | D20: preview画面与拍出来的画面四周无噪点、无色偏、无水波纹、无失真、无太暗或太亮、无画面延迟等问题
B21: 2.8 | C21: 于日光环境下,执行camera程序切到后镜头进行录像(水平与垂直) | D21: preview画面与录像的影片四周无噪点、无色偏、无水波纹、无失真、无太暗或太亮、无画面延迟等问题
B22: 3.闪光灯
B23: 3.1 | C23: 打开后置摄像头，关闭闪光灯，进行拍照 | D23: 拍照时闪光灯不可亮起
B24: 3.2 | C24: 打开后置摄像头，打卡闪光灯，进行拍照 | D24: 拍照时闪光灯亮起
B25: 3.3 | C25: 打开后置摄像头，开启闪光灯自动模式，进行拍照 | D25: 在明亮的环境下拍照时闪关灯不可亮起，在较暗的环境下拍照闪光灯亮起
B26: 4.AC/DC
B27: 4.1 | C27: 插入AC电源，观察前后CAM是否有异常情况；进行以上测试 | D27: 1，点击CAM，确认APK是否可以打开并preview画面，前后摄像头是否可以转换。 2，preview画面与录像的影片四周无噪点、无色偏、无水波纹、无失真、无太暗或太亮、无画面延迟等问题
B28: 4.2 | C28: 拔掉AC电源，观察前后CAM是否有异常情况；进行以上测试 | D28: 1，点击CAM，确认APK是否可以打开并preview画面，前后摄像头是否可以转换。 2，preview画面与录像的影片四周无噪点、无色偏、无水波纹、无失真、无太暗或太亮、无画面延迟等问题
F30: =COUNTA(E27:E28,E23:E25,E14:E21,E3:E12)/COUNTA(D3:D12,D14:D21,D23:D25,D27:D28) -> 0

Sheet GPS
B1: NO. | C1: 测试项目 | D1: 判断标准 | E1: 结果 | F1: 备注
B2: 1.GPS function
B3: 1.1 | C3: 打开地图，在地图中可定位到本机位置 | D3: 关闭WLAN及SIM卡网络，使用GPS可定位到本机位置
B4: 1.2 | C4: 定位可实时变化 | D4: 1.关闭WLAN及SIM卡网络，使用GPS可定位到本机位置 2.变更平板位置，地图中的位置随之更改
B5: 1.3 | C5: GPS测试软件 | D5: 使用GPS定位软件可以得到准确数据
F6: =COUNTA(E3:E5)/COUNTA(D3:D5) -> 0

Sheet LTE
B1: NO. | C1: 测试项目 | D1: 判断标准 | E1: 结果 | F1: 备注
B2: 1. 移动数据
B3: 1.1 | C3: 移动数据功能启动确认 1.关机时插上SIM卡 2.开机后，确认移动数据功能默认为开启(SW Spec) 3.开启浏览器上网 5.重开机，确认每次开机进入系统是否移动数据功能为ON 6.睡眠唤醒回来是否移动数据为ON | D3: 1.符合SW SPEC要求，在Status bar的移动数据功能 icon打开，水平与垂直图形及文字显示正常不可被裁切，可以正常联机上网 2...->Mobile networks->Access Point Names(APN)观看,预设APN须为"internet"
B4: 1.2 | C4: 移动数据功能关闭确认测试 1.关机时插上SIM卡 2.开机后，将移动数据功能关闭 3.开启浏览器确认无法上网 4.重开机，每次开机进入系统是否移动数据功能为off 5.睡眠唤醒回来是否移动数据功能为off | D4: 符合SW SPEC要求，在Status bar的移动数据功能 icon无异常(有讯号强度icon，无3G连接速度icon)，无法联机上网
B5: 1.3 | C5: 移动数据 连接时间测试 1.开机后，进入系统至解锁画面时，开始计算移动数据网络连接时间(系统列出现移动数据 icon为止), 并可浏览器上网 2.反复测试三次 | D5: 开机至解锁画面时，移动数据 icon应10秒内出现
B6: 1.4 | C6: 休眠时移动数据传输数据测试 1.移动数据开启&连接 2.平板及PC端分别安装微信后登入,平板休眠后,从PC传讯息给平版 4.平板后台可接受到微信信息 | D6: 进入Suspend状态后,数据传输保持开启状态(网络电台持续播放、通讯软件可接受讯息,ping有响应)
B7: 1.5 | C7: 数据传输休眠唤醒后联机测试 1.确认数据传输功能正常可上网 2.按Power Button进入休眠 3.等一分钟后再按Power Button唤醒 3.开启浏览器上网 | D7: 数据传输可以从休眠唤醒后正常联机上网
B8: 1.6 | C8: WiFi基地台->数据传输自动切换测试 1.确认数据传输功能正常可上网 2.开启WiFi,若有连接过其他WiFi基地台成功的记录,须先清除所有联机纪录 3.连接上某WiFi基地台成功 4.把某WiFi基地台关闭(或确认已远离此WiFi讯号范围) | D8: WiFi基地台关闭(或确认已远离此WiFi讯号范围),会自动切换到数据传输上网(WiFi基地台关闭起算,直到平板Status bar的wifi熄灭为止)
B9: 1.7 | C9: 数据传输->WiFi基地台自动切换测试 1.确认数据传输功能正常可上网 2.开启WiFi,若有连接过其他WiFi基地台成功的记录,须先清除所有联机纪录 3.连接上某WiFi基地台成功 4.把某WiFi基地台关闭(或确认已远离此WiFi讯号范围) 5.再把某WiFi基地台开启(或确认已接近此WiFi讯号范围) | D9: WiFi基地台开启(或确认已接近此WiFi讯号范围),会自动切换到WiFi上网(WiFi基地台开机完成后起算,直到平板的Status bar出现WiFi连接图示),须在10秒内切换完成.
B10: 2.移动数据网络共享
B11: 2.1 | C11: 启动移动数据WLA分享上网功能 1.确认移动数据功能正常可上网 2.打开WLAN热点，设置无密码 | D11: 1.其它WIFI装置可侦测到，并可联机上网
B12: 2.2 | C12: 热点名称更换 1.确认移动数据功能正常可上网 2.打开WLAN热点设置 3.修改输入SSID | D12: 水平与垂直图形及文字显示正常不可被裁切，其它WIFI装置可侦测到新的SSID
B13: 2.3 | C13: 热点加密设定 1.确认移动数据功能正常可上网 2.打开WLAN热点设置 3.修改输入热点密码 | D13: 水平与垂直图形及文字显示正常不可被裁切，其它WIFI装置可侦测到并可联机输入正确密钥后可上网
B14: 2.4 | C14: 平板休眠后,移动数据分享上网功能仍可以使用 1.确认移动数据功能正常可上网 2.打开WLAN热点设置 3.PC端以WiFi联机到平板仿真的无线基地台 4.平板按Power button进入休眠 5.PC端可上网,及ping www.baidu.com -t 约10分钟 | D14: 平板休眠后,打开WLAN热点设置分享上网功能仍可以使用,PC端仍可上网及ping仍有回应
B15: 2.5 | C15: 关闭移动数据WLA分享上网功能 | D15: 关闭后，其它WIFI装置无法侦测之前可联机的SSID
B16: 2.6 | C16: 启动移动数据UAB分享上网功能 1.确认移动数据功能正常可上网 2.打开USB网络共享，通过原装USB线连接平板与PC | D16: PC可以通过USB连接线共享到平板网络可正常上网
B17: 2.7 | C17: 启动移动数据蓝牙分享上网功能 1.确认移动数据功能正常可上网 2.打开蓝牙网络共享，通过蓝牙连接平板与PC | D17: PC可以通过接入平板蓝牙共享到平板网络可正常上网
B18: 3. SIM card
B19: 3.1 | C19: 设定SIM PIN码锁 1.Settings->Security->SIM card lock->Set up SIM card lock->Lock SIM card->Enable 2.关机重开机 | D19: 水平与垂直图形及文字显示正常不可被裁切，有秀出SIM卡PIN码锁项目
B20: 3.2 | C20: 更换SIM PIN码 1.Settings->Security->SIM card lock->Set up SIM card lock->Lock SIM card->Change SIM PIN 2.关机重开机 | D20: 水平与垂直图形及文字显示正常不可被裁切，输入更改后的号码可正常解锁进入系统
B21: 3.3 | C21: PUK code测试 1.故意将SIM卡的PIN码输入3次错误后，会跳出要求输入PUK code | D21: 要能跳出PUK码输入的画面，且能正确的输入PUK code及新的PIN码后进入系统
B22: 3.4 | C22: PUK code测试 1.故意将SIM卡的PIN码输入3次错误后，会跳出要求输入PUK code 2.故意输入错误PUK code3次后，强制关机再开机 | D22: 重开机后,要能跳出PUK码输入的画面
B23: 3.5 | C23: SIM PIN码锁取消 1.Settings->Security->SIM card lock->Set up SIM card lock->Lock SIM card->Disable 2.关机重开机 | D23: 不会出现SIM卡PIN码锁，直接进入系统
B24: 4.简讯功能&拒绝接收来电
B25: 4.1 | C25: 发送简讯: 开启简讯程序后，点选新增简讯，分别输入要传送的手机号码和输入讯息后，按Enter后传送。 | D25: 确认对方手机有接收到简讯讯息。
B26: 4.2 | C26: 接收简讯: 利用其它手机发送一则简讯给有3G功能的平版，在系统状态栏中会出现发送端的手机号码和简讯的ICON。 | D26: 开启此则简讯确认可以阅读。(点选简讯的Icon后，会开启简讯程序。)
B27: 4.3 | C27: 拒绝接收来电: 利用其它电话(市话or手机)拨打平板的SIM Card电话门号后，平板不能出现任何有关来电的讯息。 | D27: 平板不能出现任何有关来电的讯息。
B28: 5.相关选项list
B29: 5.1 | C29: 应用程序/简讯(Messaging) | D29: 有入网许可的设备有此APK
B30: 5.2 | C30: Settings/More…/Mobile networks | D30: spec无移动数据装置者,此项目不可以出现
B31: 5.3 | C31: Settings/Data usage/Mobile data | D31: spec无移动数据装置者,此项目不可以出现
B32: 5.4 | C32: 1.Settings/Data Usage/Mobile/设定行动数据限制上限(Set mobile data limit) 2.Settings/Data Usage/Menu键->Restrict background data(限制背景资料) 3.Settings/Data Usage/Menu键->Data roaming(漫游服务) | D32: spec无移动数据装置者,此项目不可以出现
B33: 5.5 | C33: Settings/About tablet/Status/我的电话号码(Phone number)、网络(Network)、讯号强度(Signal strength)、行动网络类型(Mobile network)、服务状态(Service state)、漫游(Roaming)、行动网络状态(Mobile network state)、MDN、IMEI、IMEI SV | D33: spec无移动数据装置者,此项目不可以出现
B34: 5.6 | C34: Settings/About tablet/基频版本(Baseband version) | D34: spec无移动数据装置者,此项目不可以出现
B35: 5.7 | C35: 点选系统状态栏:连接的3G服务商名称、讯号强度条 | D35: spec无移动数据装置者,此项目不可以出现
B36: 5.8 | C36: Settings /Date & time(日期与时间)/自动判定时区(Automatic time zone) | D36: spec无移动数据装置者,此项目不可以出现
F38: =COUNTA(E29:E36,E25:E27,E19:E23,E11:E17,E3:E9)/COUNTA(D3:D9,D11:D17,D19:D23,D25:D27,D29:D36) -> 0

Sheet WIFI
B1: NO. | C1: 测试项目 | D1: 判断标准 | E1: 结果 | F1: 备注
B2: 1.WiFi功能设定
B3: 1.1 | C3: 刷完Image或FactoryReset后,第一次Wifi功能开启(SW SPEC默认为ON) settings->Wifi->将OFF bar滑动至ON | D3: Wifi可切至开启,可扫描到基地台并连接
B4: 1.2 | C4: Wifi功能启动确认 1.连接任一可上网之AP 2.右下方系统信息是否有Wifi的ICON出现 | D4: 右上角系统信息会出现Wifi的icon
B5: 1.3 | C5: Wifi功能关闭 settings->Wifi->将ON bar滑动至OFF | D5: 右上角系统信息Wifi的icon会消失，且无法连网络
B6: 2.WiFi连接测试
B7: 2.1 | C7: AP搜寻测试 1.Settings->Wi-Fi->点选SCAN钮,并跟对比机比较 | D7: 扫描出的基地台数量及讯号强度跟对比机的要接近相等
B8: 2.2 | C8: 网页连接时间测试 连接任一可上网之AP后，开启浏览器 1.开启baidu手机(mobile)版网页:http://m.baidu.com 2.开启baidu计算机(PC)版网页:http://www.baidu.com 3.开启youku 手机(mobilep)版网页:http://m.youku.com 4.开启youku 计算机(Desktop)版网页:http://www.youku.com | D8: 1.网页载入完成低于5秒 2.网页载入完成低于5秒 3.网页载入完成低于10秒 4.网页载入完成低于10秒
B9: 3.WiFi自由测试
B10: 3.1 | C10: Wifi 压力测试-下载200MB档案: | D10: 下载完成
B11: 3.2 | C11: Wifi 压力测试-上传200MB档案: | D11: 上传完成
B12: 3.3 | C12: 长时间休眠时Wifi联机测试 1.Wi-Fi开启&连接到基地台 2.开启网络电台Tuneln Radio APK，并连上任一电台播放 3.使机器进入Suspend状态12小时,以PC计算机在同一网络区段中ping 平板(Tablet的IP address可在Settings/Wi-Fi/Menu钮/Advanced中查看) | D12: 进入Suspend状态后,Wifi仍保持开启状态(网络电台持续播放、ping有响应)
B13: 4.wifi数据网络共享
B14: 4.1 | C14: 启动wifi WLA分享上网功能 1.确认wifi功能正常可上网 2.打开WLAN热点，设置无密码 | D14: 1.其它WIFI装置可侦测到，并可联机上网
B15: 4.2 | C15: 热点名称更换 1.确认wifi功能正常可上网 2.打开WLAN热点设置 3.修改输入SSID | D15: 水平与垂直图形及文字显示正常不可被裁切，其它WIFI装置可侦测到新的SSID
B16: 4.3 | C16: 热点加密设定 1.确认wifi功能正常可上网 2.打开WLAN热点设置 3.修改输入热点密码 | D16: 水平与垂直图形及文字显示正常不可被裁切，其它WIFI装置可侦测到并可联机输入正确密钥后可上网
B17: 4.4 | C17: 平板休眠后,wifi分享上网功能仍可以使用 1.确认wifi功能正常可上网 2.打开WLAN热点设置 3.PC端以WiFi联机到平板仿真的无线基地台 4.平板按Power button进入休眠 5.PC端可上网,及ping www.baidu.com -t 约10分钟 | D17: 平板休眠后,打开WLAN热点设置分享上网功能仍可以使用,PC端仍可上网及ping仍有回应
B18: 4.5 | C18: 关闭wifi WLA分享上网功能 | D18: 关闭后，其它WIFI装置无法侦测之前可联机的SSID
B19: 4.6 | C19: 启动wifi UAB分享上网功能 1.确认wifi功能正常可上网 2.打开USB网络共享，通过原装USB线连接平板与PC | D19: PC可以通过USB连接线共享到平板网络可正常上网
B20: 4.7 | C20: 启动wifi 据蓝牙分享上网功能 1.确认wifi功能正常可上网 2.打开蓝牙网络共享，通过蓝牙连接平板与PC | D20: PC可以通过接入平板蓝牙共享到平板网络可正常上网
F22: =COUNTA(E14:E20,E10:E12,E7:E8,E3:E5)/COUNTA(D14:D20,D10:D12,D7:D8,D3:D5) -> 0

Sheet SIM
B1: NO. | C1: 测试项目 | D1: 判断标准 | E1: 结果 | F1: 备注
B2: 1.识别SIM
B3: 1.1 | C3: 1、插入移动/联通或电信SIM卡，测试机正常开机； 2、进行搜网注册，拨号，语音，短信收发等基本的业务功能 | D3: 1、测试机可以正确识别SIM卡，并注册上网络，网络图标有明确的网络标识； 2、业务功能可以正常运行
B4: 1.2 | C4: 1、未插入SIM卡启动系统，查看系统是否有无SIM卡提示； 2、验证搜网、拨号、语音、短信功能是否正常； 3、关闭系统，插入SIM卡，再启动系统，查看系统是否有无SIM卡提示； 4、验证搜网、拨号、语音、短信功能是否正常 | D4: 1、系统启动后，系统主界面显示“没有SIM卡，请插SIM卡”的； 2、不能进行搜网、拨号、语音、短信功能； 3、插入SIM卡，再启动系统后，提示消失； 4、能正常进行搜网、拨号、语音、短信功能
B5: 2.SIM卡电话本地测试
B6: 2.1 | C6: 1、请确保SIM卡里面至少有一个联系人记录，插入SIM卡，测试机正常开机； 2、拨号界面输入“*#*#4636#*#*” ->“平板电脑信息”->“查看SIM卡地址薄”，选择某一个联系人长按选择“导入”； | D6: 1、进入联系人程序可查看到SIM卡中所有联系人记录； 2、联系人记录成功被导入到本地且信息无误
B7: 2.2 | C7: 1、请确保SIM卡里面至少有一个联系人记录，插入SIM卡，测试机正常开机； 2、拨号界面输入“*#*#4636#*#*” ->“平板电脑信息”->“查看SIM卡地址薄”->“全部导入”； | D7: 1、进入联系人程序可查看到SIM卡中所有联系人记录； 2、联系人记录成功被导入到本地且信息无误
B8: 2.3 | C8: 设置>SIM卡管理>其他设置 1、国际漫游>数据漫游>点选对应运营商>弹出提示界面>确定 1.1 国际漫游>显示漫游提醒>显示提醒方式>选择任一选项，退回上一层 2、 联系人绑定>SIM卡与联系人>选择运营商>添加联系人界面>添加所需联系人 | D8: 1、能选中对应的运营商，无报错 1.1 选择对应选项无报错。选择后保存选项 2、选择对应选项无报错，联系人添加成功
B9: 2.4 | C9: 设置>SIM卡管理>SIM卡信息 1、滑动icon>启用或禁用SIM卡 2、点击SIM卡信息，能够进入“SIM卡信息“界面，对SIM名称、号码、背景颜色、号码显示进行编辑 | D9: 1、向左滑动按钮，禁用SIM卡；向右滑动按钮，启用SIM卡 2、可以对SIM名称、号码、背景颜色、号码显示进行编辑 ，并保存
B10: 3.短信收发
B11: 3.1 | C11: 选择一个联系人创建并发送短信 1、点开联系人程序； 2、选择一个联系人，并编辑一条短信发送 | D11: 1、可以打开联系人程序看到通讯录列表； 2、可以创建短信并成功发送出短信
B12: 3.2 | C12: 关机接收短息 1、测试机短信箱未满； 2、测试机关机状态； 3、已设置将短息保存到本地; 4、从辅助终端B向测试机发送息; 5、发送完毕后启动测试机系统 | D12: 1、短信接收完全，无遗漏、错误
B13: 3.3 | C13: 开机接收短息 1、测试机短信箱未满； 2、测试机开机状态； 3、已设置将短信保存到本地; 4、从辅助终端B向测试机发送大量短息（超过SIM本身容量） | D13: 1、短信接收完全，无遗漏、错误
B14: 3.4 | C14: 短信中心号码 1、插入SIM卡启动系统； 2、打开系统主菜单，点击拨号，在拨号界面输入“*#*#4636#*#*” 3、打开手机Messaging界面，点击刷新，查看短信中心号码； 4、从串口工具输入AT+CSCA？命令，查看短信中心号码，比较二者是否一致； 5、打开手机Messaging界面，向短信中心号码发送一条短信 | D14: 1、从手机Messaging界面查看到的短信中心号码与使用AT命令查看的一致； 2、可以正常更新； 3、短信可以成功发送
B15: 4.编辑短信
B16: 4.1 | C16: 阅读并删除SIM卡中所有的短信 1、打开（SIM卡中至少有两条短信）Messaging，进入“短信设置”->“管理SIM卡中的信息” 2、查看SIM卡中的信息； 3、选择“删除信息”，选择删除所有短信 | D16: 1、可以显示SIM卡中所有短信，显示不能有错误； 2、可以删除SIM卡中所有的短信
B17: 4.2 | C17: 编辑短信常用语 1、打开Messaging,进入“短信设置”->“编辑短信常用语” 2、点击一条短信常用语，进行编辑并保存； 3、添加一条，并输入新的的语句保存； 4、删除任意一条短信常用语 | D17: 1、可以查看到短信常用语，且无显示错误； 2、可以编辑短信常用语并进行保存； 3、可以完成添加新短信常用语； 4、可以删除短信常用语
B18: 4.3 | C18: 从信息中的号码选中添加为联系人 1、从辅助终端发送一条写有自己手机号码的信息给测试机； 2、测试机打开短信选择号码并在弹出的窗口选择“添加到联系人” 3、编辑联系人并保存 | D18: 1、测试机可收到短信息； 2、选择短信息中的号码会弹出窗口； 3、可编辑联系人并保存成功
F20: =COUNTA(E16:E18,E11:E14,E6:E9,E3:E4)/COUNTA(D3:D4,D6:D9,D11:D14,D16:D18) -> 0

Sheet Bluetooth
B1: NO. | C1: 测试项目 | D1: 判断标准 | E1: 结果 | F1: 备注
B2: 1.功能设定
B3: 1.1 | C3: 刷完Image或FactoryReset后,第一次蓝牙功能开启 settings->Bluetooth->将OFF bar滑动至ON | D3: 蓝牙可切至开启,扫描到蓝芽设备
B4: 1.2 | C4: 蓝牙功能启动确认 右上方系统信息是否有蓝牙的ICON出现 | D4: 右上角系统信息会出现Bluetooh的icon
B5: 1.3 | C5: 被侦测测试 1.点选settings->Bluetooth->XXXX(Buletooth name)开启可被搜寻模式 2.在其它的蓝牙装置，如PC，开启蓝牙管理工具去搜寻Tablet | D5: 在其它的蓝牙装置可搜寻到Tablet装置
B6: 1.4 | C6: 蓝牙功能关闭 settings->Bluetooth->将ON bar滑动至OFF | D6: 右上角系统信息Bluetooh的icon会消失
B7: 2.功能测试-PC
B8: 2.1 | C8: Tablet连接PC装置配对测试 1.蓝牙开启 2.Tablet点选SEARCH FOR DEVICES，搜寻到欲连接的PC装置，点选后会出现Bluetooth pairing request窗口，输入devices's required PIN码，预设用0000四码，此时PC端也会出现密钥窗口，输入0000， | D8: 配对成功，PC装置就会出现在PAIRED DEVICES中
B9: 2.2 | C9: Tablet传送档案至PC 1.Tablet可透过iFileManager档案总管选择档案(MP3)，长按档案出现传送后，点选选择蓝牙，再选择接收端PC，传送档案 | D9: 可正常传送完毕，并可在PC上播放传送完毕的MP3档
B10: 2.3 | C10: Tablet休眠下传送档案至PC 1.Tablet可透过iFileManager档案总管选择档案(MP3)，长按档案出现传送后，点选选择蓝牙，选择接收端PC，传送档案 2.按POWER键强制进入休眠or Screen time out设定15秒，让Tablet自动进入休眠 | D10: 可正常在休眠下传送完毕，并可在PC上播放传送完毕的MP3档
B11: 2.4 | C11: PC传送档案至Tablet 1.在PC端选择一档案(MP3)，透过蓝牙传送至Tablet 2.系统列会出现Bluetooth share:Incoming file点选接收 | D11: 可正常传送完毕，并可在Tablet上播放传送完毕的MP3档
B12: 2.5 | C12: PC传送档案至Tablet,休眠下可继续接收 1.在PC端选择一档案(MP3)，透过蓝牙传送至Tablet 2.系统列会出现Bluetooth share:Incoming file点选接收 3.接收后按POWER键强制进入休眠or Screen time out设定15秒，让Tablet自动进入休眠 | D12: 可正常在休眠下传送完毕，并可在Tablet上播放传送完毕的MP3档
B13: 2.6 | C13: 装置更名测试 1.点选已配对装置功能ICON 2.点选Rename，输入自定义的名称 | D13: 装置名称会变更为所自定义的名称
B14: 2.7 | C14: 解除配对测试 1.点选已配对装置功能ICON 2.点选Unpair解除配对 | D14: 原已配对装置会由PAIRED DEVICES名单中消失
B15: 3.功能测试-Tablet
B16: 3.1 | C16: Tablet连接另一Tablet装置配对测试 1.蓝牙开启 2.点选SEARCH FOR DEVICES，搜寻到欲连接的Tablet装置，点选后会出现Bluetooth pairing request窗口，输入devices's required PIN码，预设用0000四码，此时Tablet端也会出现密钥窗口，输入0000 | D16: 配对成功，Tablet装置就会出现在PAIRED DEVICES中
B17: 3.2 | C17: Tablet传送档案至另一Tablet 1.Tablet可透过档案总管选择档案(MP3)，长按档案出现传送后，点选选择蓝牙，再选择接收端Tablet，传送档案(若内建的档案总管无蓝牙传送选项，可透过第三方APK-ASTRO测试) | D17: 可正常传送完毕，并可在另一Tablet上播放传送完毕的MP3档
B18: 3.3 | C18: 另一Tablet传送档案至Tablet 1.在另一Tablet端选择一档案(MP3)，透过蓝牙传送至Tablet 2.系统列会出现Bluetooth share:Incoming file点选接收 | D18: 可正常传送完毕，并可在Tablet上播放传送完毕的MP3档
B19: 3.4 | C19: 装置更名测试 1.点选已配对装置功能ICON 2.点选Rename，输入自定义的名称 | D19: 装置名称会变更为所自定义的名称
B20: 3.5 | C20: 解除配对测试 1.点选已配对装置功能ICON 2.点选Unpair解除配对 | D20: 原已配对装置会由PAIRED DEVICES名单中消失
B21: 4.功能测试-HID
B22: 4.1 | C22: 蓝牙鼠标配对(测试装置：Logitech Bluetooth Laser Travel Mouse) 1.蓝牙开启 2.点选SEARCH FOR DEVICES，搜寻到欲连接的蓝牙鼠标装置 3.配对，输入配对预设PIN码，预设通常是0000 | D22: 可配对及功能可正常使用，会出现鼠标鼠标，可点选程序，左键长按可滑动桌面
B23: 4.2 | C23: 蓝牙鼠标配对:S3唤醒后回连测试 1.按Power button后进入休眠 2.待三十秒后，再按Power button唤醒 3.点选鼠标任意键回连 | D23: 唤醒后可以正常自动回连使用蓝牙鼠标操作
B24: 4.3 | C24: 蓝牙鼠标配对:重开机后回连测试 1.关机重新启动 2.点选鼠标任意键回连 | D24: 可以正常回连使用蓝牙鼠标操作
B25: 4.4 | C25: 蓝牙键盘配对(测试装置：Logitech MX5500 Keyboard) 1.蓝牙开启 2.点选SEARCH FOR DEVICES，搜寻到欲连接的蓝牙键盘装置 3.配对，输入配对PIN码 | D25: 确认功能可使用 英文大小写Aa-Zz 数字符号123 特殊符号!@# 功能键BackSpace Esc
B26: 4.5 | C26: 蓝牙键盘配对:S3唤醒后回连测试 1.按Power button后进入休眠 2.待三十秒后，再按Power button唤醒 3.点选键盘任意键回连 | D26: 唤醒后可以正常回连使用蓝牙键盘操作
B27: 4.6 | C27: 蓝牙键盘配对:重开机后回连测试 1.关机重新启动 2.点选键盘任意键回连 | D27: 可以正常回连使用蓝牙键盘操作
B28: 4.7 | C28: 装置更名测试 1.点选已配对装置功能ICON 2.点选Rename，输入自定义的名称 | D28: 装置名称会变更为所自定义的名称
B29: 4.8 | C29: 解除配对测试 1.点选已配对装置功能ICON 2.点选Unpair解除配对 | D29: 原已配对装置会由PAIRED DEVICES名单中消失
B30: 5.功能测试-A2DP(耳机+麦克风)
B31: 5.1 | C31: Tablet连接A2DP装置测试 1.蓝牙开启 2.点选SEARCH FOR DEVICES，搜寻到欲连接的蓝牙耳机装置 3.配对 | D31: 配对成功，A2DP装置就会出现在PAIRED DEVICES中
B32: 5.2 | C32: 确认A2DP长距离联机功能 1.点选装置上的play会自动开启music程序播放音乐 2.距离平板2公尺听完1首歌 | D32: 可连接2公尺装置,听完1首歌,音乐无间断停顿
B33: 5.3 | C33: A2DP功能休眠测试 1.开启music程序播放音乐 2.按power button进入休眠 | D33: 过三十秒后音乐还是会持续由装置输出
B34: 5.4 | C34: A2DP功能重开机后回连测试 1.关机重新启动 2.点选play回连 | D34: 正常回连并播放音乐
B35: 5.5 | C35: 装置更名测试 1.点选已配对装置功能ICON 2.点选Rename，输入自定义的名称 | D35: 装置名称会变更为所自定义的名称
B36: 5.6 | C36: 解除配对测试 1.点选已配对装置功能ICON 2.点选Unpair解除配对 | D36: 原已配对装置会由PAIRED DEVICES名单中消失
B37: 5.7 | C37: 1、设置>打开蓝牙并搜索设备，让附近所有蓝牙设备均可检测到平板 2、长按蓝牙耳机直到红蓝交替时放开>打开蓝牙耳机>平板搜索到蓝牙耳机名称 3、触摸蓝牙耳机名称>使其与平板与成功配对>拨号并使用蓝牙耳机通话 | D37: 1、平板蓝牙正常打开并搜索到蓝牙耳机 2、点击蓝牙耳机名称可成功配对 3、拨号时蓝牙耳机接收到拨号声音，能用蓝牙耳机接听和挂断电话 4、在蓝牙耳机的接收信号范围内接听电话声音正常，无杂音
B38: 5.8 | C38: 蓝芽耳机麦克风(搭配视频通话软件) 1.平板连接蓝牙耳麦 2.安装视频通话软件进行通话 | D38: 蓝牙耳机可以听到对方传来的声音,蓝芽麦克风可把声音送给对方
B39: 6.Bluetooth File type transfer
B40: 6.1 | C40: 以档案总管软件经蓝芽发送图片，PC端接收 | D40: 可发送完成，且可以正常打开文件
...

Sheet Sensors
B1: NO. | C1: 测试项目 | D1: 判断标准 | E1: 结果 | F1: 备注
B2: 1.G-sensor
B3: 1.1 | C3: 到Settings/Display/Auto-rotate勾选,平板旋转四个方向 | D3: 平板转方向，2sec内屏幕也会跟着旋转
B4: 1.2 | C4: 到Settings/Display/Auto-rotate勾选,进入休眠一分钟后唤醒,平板旋转四个方向 | D4: 平板转方向，2sec内屏幕也会跟着旋转
B5: 1.3 | C5: 到Settings/Display/Auto-rotate取消勾选,平板旋转四个方向 | D5: 平板转任何方向，屏幕都不会跟着旋转
B6: 1.4 | C6: 到Settings/Accessibility/Auto-rotate取消勾选,平板旋转四个方向 | D6: 平板转任何方向，屏幕都不会跟着旋转
B7: 1.5 | C7: 安装重力感应游戏 | D7: 游戏可以玩
B8: 1.6 | C8: 安装PHONETEST.APK，进入APK后点击Sensors status。 | D8: 在转动平板时，需要X,Y,Z三轴都要有数据且有变化。
B9: 2.E-compass
B10: 2.1 | C10: 1.安装Compass 3.2.1.apk程序并执行，搭配实体指南(北)针验证方向是否相同 2.摇晃或大幅度转动平版 | D10: 平板的E-compass方向和实体指南(北)针的方向应相同(或误差小于5%)
B11: 2.2 | C11: 进入休眠一分钟后唤醒,执行Compass 3.2.1.apk程序 | D11: 平板的E-compass方向和实体指南(北)针的方向应相同(或误差小于5%)
B12: 2.3 | C12: 安装Winds of Steel Demo 1.15.apk游戏 | D12: 此游戏须要有G-sensor & E-compass装置共存才可以玩 若只有G-sensor而无E-compass装置,玩游戏飞机会往下坠
B13: 2.4 | C13: [Android平板]使用网络地图Map来确认电子罗盘(E-compass)方位 安装地图软件并使用 | D13: 平板的E-compass方向和实体指南(北)针的方向应相同(或误差小于5%)
B14: 3.Gyro
B15: 3.1 | C15: 1.安装AndroSensor程序 2.执行AndroSensor/Gyroscope | D15: Gyroscope项目的数值于平板转动时才有变化,平板静止时无变化(X/Y/Z值都各接近为0,容许±5%误差,即+0.05~-0.05rad/s之内跳动)
B16: 3.2 | C16: 1.安装AndroSensor程序 2.执行AndroSensor/Gyroscope | D16: Gyroscope项目的数值于平板转动时才有变化,平板静止时无变化(X/Y/Z值都各接近为0,容许±5%误差,即+0.05~-0.05rad/s之内跳动)
B17: 4.Light sensor
B18: 4.1 | C18: 1.安装AndroSensor程序 2.执行AndroSensor/Light sensor | D18: Light sensor项目的数值有依环境亮暗而变化
B19: 4.2 | C19: 1.安装AndroSensor程序 2.执行AndroSensor/Light sensor | D19: Light sensor项目的数值有依环境亮暗而变化
B20: 4.3 | C20: 1.Settings/Screen/Brightness/Automatic brightness勾选 2.依据SPEC文件的Light sensor v.s. Backlight Brightnes的比对表，AndroSensor程序观看Light sensor数值,Quick System Info PRO->View Logs->Dmesg看Backlight level数值,在各种环境下是否互相匹配(符合比对表内容) 3.分别在不开灯的会议室、有开灯的会议室、户外的阴影处、户外的强光下,做使用者体验测试 | D20: 1.Light sensor与Backlight Brightnes的匹配符合SPEC标准 2.在各种亮度环境下,体验自动屏幕亮度调整,是否舒适可用,不会太暗或太亮
B21: 5.Vibrator
B22: 5.1 | C22: 到Settings/Sound/Haptic feedback勾选,按软件Home键 | D22: 确认有振动
B23: 5.2 | C23: 到Settings/Sound/Haptic feedback勾选,进入休眠一分钟后唤醒,按软件Home键 | D23: 确认有振动
B24: 5.3 | C24: 到Settings/Sound/Haptic feedback取消勾选,按软件Home键 | D24: 无振动
B25: 5.4 | C25: Vibrator相关选项list: 设定(Settings)\音效\系统\触控时振动; 设定(Settings)\音效\铃声与通知\振动和铃声; 设定(Settings)>安全性(Security)>屏幕锁定(Screen lock),建立完成图形(Pattern)或PIN类型的屏幕锁定,会出现触控时振动(Vibrate on touch) 设定(Settings)\语言与入装置\Android键盘设定\按键时振动; 设定(Settings)\语言与入装置\Android键盘设定\其他选项\进阶设定\按键振动持续时间设定; 日历(Calendar)APK\设定\一般设定\提醒设定\振动; 时钟(Clock)APK\设定闹钟\新增闹钟\设定闹钟\振动; 电子邮件(Email)APK\menu\设定\通知设定\振动; 简讯(Messaging)APK\menu设定\通知\振动 | D25: 功能可以使用(spec无Vibrator装置者,此项目不可以出现)
F27: =COUNTA(E22:E25,E18:E20,E15:E16,E10:E13,E3:E8)/COUNTA(D3:D8,D10:D13,D15:D16,D18:D20,D22:D25) -> 0

Sheet SW setting
B1: NO. | C1: 测试项目 | D1: 判断标准 | E1: 结果 | F1: 备注
B2: 1.HOME UI
B3: 1.1 | C3: 滑动解锁至桌面测试 1.按Power钮开机进入到预设解锁画面 2.滑动解锁钮至解锁ICON(水平与垂直) | D3: 水平与垂直图形及文字显示正常不可被裁切，可正常解锁进至桌面
B4: 1.2 | C4: 解锁画面信息确认(AC Mode) 1.按Power钮开机进入到解锁画面 2.纪录解锁画面上的时间、日期与电量后解锁进入桌面 3.确认与系统列中的时间、日期与电量是否相同(水平与垂直) | D4: 解锁画面的时间、日期与和电量信息与进桌面后系统列中显示相同。
B5: 1.3 | C5: 解锁画面信息确认(BAT Mode) 1.按Power钮开机进入到解锁画面 2.纪录解锁画面上的时间、日期与电量后解锁进入桌面 3.确认与系统列中的时间、日期与电量是否相同(水平与垂直) | D5: 解锁画面的时间、日期与和电量信息与进桌面后系统列中显示相同。
B6: 1.4 | C6: Back键功能测试 1.在桌面上按back键是否有出现问题(水平与垂直) 2.点选应用程序(Apps)后，再点选设定(Settings)后按back键回上一页面(水平与垂直) | D6: 1.应无任何反应 2.可正常回到上一个画面应用程序
B7: 1.5 | C7: Home键功能测试 1.在桌面上按Home键是否有出现问题(水平与垂直) 2.点选应用程序(Apps)后，再点选设定(Settings)后按Home键回到桌面(水平与垂直) | D7: 1.应无任何反应 2.可正常回到桌面
B8: 1.6 | C8: 桌面显示正确性测试 1.检查桌面图示是否有无异常或变形及屏幕四周是否有亮线 | D8: 桌面水平与垂直图标显示正常不可变形及四周无亮线异常
B9: 1.7 | C9: 变更桌布:从图片库变更 1.在空白桌面长按，出现壁纸选择 2.点选壁纸/图库 3.选择图片 4.调整作为桌布的图片大小及范围 5.确认后点选OK | D9: 可预览图片，确认是否能变更成功，图片分辨率是否正确。
B10: 1.8 | C10: 第一个页面:应用程序能建立快捷方式到桌面(建三个快捷方式) 1.点选App Drawer后，选择任一程序长按直至出现桌面选择窗口 2.拖曳至第一桌面任一处 3.再重复1-2步骤两次 | D10: 能建立到第一桌面且可以开启程序
B11: 1.9 | C11: 第一个页面:建立文件夹 长按第一桌面上任一程序快捷方式拖曳至另一程序快捷方式上生成文件夹 | D11: 可以成功生成文件夹
B12: 1.10 | C12: 第一个页面:文件夹名称变更 1.点选文件夹，展开后，再点选"未命名的文件夹" 2. | D12: 可以成功变更文件夹名称
B13: 1.11 | C13: 第一个页面:删除应用程序快捷方式及文件夹 将第一桌面上的程序快捷方式及文件夹长按拖曳至上方Remove处移除 | D13: 可以成功删除应用程序快捷方式及文件夹
B14: 1.12 | C14: 第二个页面:应用程序能建立快捷方式到桌面(三个) 1.点选App Drawer后，选择任一程序长按直至出现桌面选择窗口 2.拖曳至第二桌面任一处 3.再重复1-2步骤两次 | D14: 能建立到第二桌面且可以开启
... B20: 1.18 | C20: 网络搜寻可成功启动搜寻功能 1.平板可连接上网(经由WiFi或3G) 2.点选桌面左上Google图示 | D20: 可联机搜寻与"tongfang"相关网页
B21: 2.Status bar
B22: 2.1 | C22: 观察系统状态栏右上角及左上角: 1.时间 2.电池 | D22: 1.时间图示会变动 2.有电池电量图示,插AC充电时有闪电图示,电池充满电时闪电消失，下拉可出现具体电量
B23: 2.2 | C23: 观察系统状态栏右下角:有支援3G 1.若无插入SIM卡,WiFi无连接 2.若有插入SIM卡,WiFi无连接,3G连接上网(Settings->More...>Mobile networks->Data enabled勾选) 3.若有插入SIM卡,WiFi无连接,3G无连接上网(Settings->More...>Mobile networks->Data enabled不勾选) | D23: 1.会显示无SIM卡图标 2.会显示直角三角形的讯号强度条、连接速度符号(H/3G/G)及资料上/下传(正/倒三角形)符号 3.会显示直角三角形的讯号强度条
B24: 2.3 | C24: 点选系统状态栏右上角 | D24: 跳出状态基本栏,确认 年月日/星期/时间、电池百分比电量、连接上网状态(没有因特网联机or连接的无线基地台名称or连接的3G服务商名称)是否显示正常
B25: 2.4 | C25: 下拉系统状态栏,再下拉跳出窗口最上方的基本栏,会再跳出快速选单: 1.WiFi图示 2.BT图示 3.勿扰 4.手电筒 5.自动旋转屏幕开关 6.省电模式 7.移动数据 8.飞行模式 9.投射屏幕 10.背光亮度调整 11.SIM卡状态、用户设置、编辑按钮、设置按钮 | D25: 以下功能开启或关闭后功能需要符合其状态 1.可开启或关闭WIFI 2.可开启或关闭BT 3.可开启或关闭勿扰模式 4.可开启或关闭手电筒 5.可开启或关闭自动旋转屏幕功能 6.可开启或关闭省电模式 7.可开启或关闭移动数据 8.可开启或关闭飞行模式 9.可开启或关闭投射屏幕 10.可手动调整屏幕背光亮度明暗,若有支持自动调整亮度spec,会有自动调整亮度开关 11.SIM卡状态、用户设置、编辑按钮、设置按钮可正常使用，状态、功能对应
B26: 3.Settings/Device-Sound
B27: 3.1 | C27: 1.系统休眠后唤醒确认音量是否维持不变 2.系统关机后重启确认音量是否维持不变 | D27: 1.休眠唤醒音量需维持不变 2.关机重启音量需维持不变
B28: 3.2 | C28: Sound/Volumes/Music,video…单独音量测试: 1.调整音乐、影片、游戏及其他媒体(Music,video...)的音量调大 2.调整通知(Notifications)与闹钟(Alarms)的音量调到最小 3.测试音乐、影片、游戏、软件按键音、收到邮件通知、行事历通知、闹钟响 | D28: 1.测试音乐、影片、游戏、软件按键音音量会随着设定音量大小而变化 2.测试收到邮件通知、行事历通知、闹钟响系统不可发出声音
B29: 3.3 | C29: Sound/Volumes/Notifications单独音量测试: 1.调整通知(Notifications)的音量调大 2.调整音乐、影片、游戏及其他媒体(Music,video...)与闹钟(Alarms)的音量调到最小 3.测试音乐、影片、游戏、软件按键音、收到邮件通知、行事历通知、闹钟响 | D29: 1.测试收到邮件通知、行事历通知音量会随着设定音量大小而变化 2.测试音乐、影片、游戏、软件按键音、闹钟响系统不可发出声音
B30: 3.4 | C30: Sound/Volumes/Alarms单独音量测试: 1.调整闹钟(Alarms)的音量调大 3.调整音乐、影片、游戏及其他媒体(Music,video...)与通知(Notifications)的音量调到最小 4.测试音乐、影片、游戏、软件按键音、收到邮件通知、行事历通知、闹钟响 | D30: 1.测试闹钟响音量会随着设定音量大小而变化 2.测试音乐、影片、游戏、软件按键音、收到邮件通知、行事历通知系统不可发出声音
B31: 3.5 | C31: Sound/Volumes与实体按键同步: 1.调整音乐、影片、游戏及其他媒体(Music,video...)的音量最大后按下确定离开音量设定 3.将HW音量钮往下调整至静音观察音量是否从最大往下降低至静音 4...)的音量是否为静音 | D31: 设定中的音量调整必须与HW音量钮的调整同步
B32: 3.6 | C32: 1."On The Hunt"变更为其他铃声按下确定(OK) 4.点选音量后调整通知音量bar系统发出铃声是否跟着改变 5.测试收到邮件通知、行事历通知系统发出铃声是否跟着改变 6.系统休眠后唤醒测试音量与铃声是否不变 7.系统关机后重启测试音量与铃声是否不变 | D32: 1.预设通知铃声为"On The Hunt" 2.文字和图片显示正常不可被裁切 3.通知铃声变更如测试人员所选择 4.休眠唤醒音量与铃声不可改变 5.关机重启音量与铃声不可改变
B33: 3.7 | C33: 观察 设定>装置>>音效>铃声与通知>振动和铃声(Vibrate and ring) | D33: 若Spec无Vibrator,不能出现此"振动和铃声(Vibrate and ring)"项目
B34: 3.8 | C34: 1.设定>装置>>音效>系统>触控音效(Touch sounds) 2.测试点击设定、Home键、相机程序,系统是否发出声音 3.取消触控音效设定勾选,测试点击设定、Home键、相机程序,系统是否发出声音 4.系统休眠后唤醒确认触控音效设定值是否改变 5.系统关机后重启确认触控音效设定值是否改变 | D34: 1.触控音效默认值为勾选 2.测试点击设定、Home键、相机程序,系统需发出声音 3.取消触控音效设定勾选,测试点击设定、Home键、相机程序,系统不可发出声音 4.休眠唤醒触控音效设定值不可改变 5.关机重启触控音效设定值不可改变
B35: 3.9 | C35: 1.设定>装置>>音效>系统>屏幕锁定音效(Screen lock sound) 2.测试进入休眠与唤醒解锁后系统是否发出声音 3.取消屏幕锁定音效设定勾选,测试进入休眠与唤醒解锁后系统是否发出声音 4.系统休眠后唤醒确认屏幕锁定音效设定值是否改变 5.系统关机后重启确认屏幕锁定音效设定值是否改变 | D35: 1.屏幕锁定音效默认值为勾选 2.测试进入休眠与唤醒解锁后系统需发出声音 3.取消屏幕锁定音效设定勾选,测试进入休眠与唤醒解锁后系统不可发出声音 4.休眠唤醒屏幕锁定音效设定值不可改变 5.关机重启屏幕锁定音效设定值不可改变
B36: 3.10 | C36: 1.设定>装置>>音效>系统>触控时振动(Vibrate on touch) 2.测试点击设定、Home键、相机程序,系统是否发出振动 3.取消触控时振动设定勾选,测试点击设定、Home键、相机程序,系统是否发出振动 4.系统休眠后唤醒确认触控时振动设定值是否改变 5.系统关机后重启确认触控时振动设定值是否改变 | D36: 1.触控时振动默认值为勾选 2.测试点击设定、Home键、相机程序,系统需发出振动 3.取消触控时振动设定勾选,测试点击设定、Home键、相机程序,系统不可发出振动 4.休眠唤醒触控时振动设定值不可改变 5.关机重启触控时振动设定值不可改变
B37: 4..Settings /Devices-Display
B38: 4.1 | C38: 1.测试退回键观察是否回到前一画面 | D38: 1.出现显示相关设定字段且文字和勾选框显示正常不可裁切 2.按下退回键需回到前一画面
B39: 4.2 | C39: 1.系统休眠后唤醒确认亮度是否维持不变 2.系统关机后重启确认亮度是否维持不变 | D39: 1.休眠唤醒亮度需维持不变 2.关机重启亮度需维持不变
B40: 4.3 | C40: 进入设定(Settings)>装置(DEVICE)>显示(Display)> 点选亮度(Brightness)>勾选自动调整亮度(Automatic brightness) | D40: 屏幕亮度会随环境亮度而自动变化 (若SPEC.无Light sensor,此选项必须不能出现)
B41: 4.4 | C41: 1.测试退回键观察是否回到前一画面 | D41: 1.按下退回键需回到前一画面,文字显示正常不可被裁切
B42: 4.5 | C42: 1.选择每一个背景后测试退回键和设定桌面 2.按下Home钮回到桌面观察桌布是否变更 3.系统休眠后唤醒确认桌布是否维持不变 4.系统关机后重启确认桌布是否维持不变 | D42: 1.文字和图片显示正常不可被裁切 2.退回键不可设定桌布并回到上一页,设定桌布可设为目前桌布 3.休眠唤醒桌布需维持不变 4.关机重启桌布需维持不变
B43: 4.6 | C43: 1.设定>装置>显示>自动旋转屏幕(Auto-rotate screen)取消勾选 2.重新启动后, 进到桌面观看方向 | D43: 1.Auto-rotate screen取消勾选后,ICS在解锁画面下,画面可以旋转 2.Auto-rotate screen取消勾选后, 重新启动后, 进入到桌面, 桌面仍然会维持Spec默认方向（即拆机时默认方向）.
B44: 4.7 | C44: 1.变更休眠时间为15秒、30秒、1分钟、2分钟、5分钟、10分钟、30分钟、永不超时(Never timeout)并测试系统闲置是否依照设定时间自动进入休眠(点了马上按码表,正负两秒PASS) 2.系统休眠后唤醒确认休眠时间是否维持不变 3.系统关机后重启确认休眠时间是否维持不变 | D44: 1.应有永不超时(Never timeout)选项，系统闲置需依照休眠设定时间自动进入休眠 2.休眠唤醒休眠时间需维持不变 3.关机重启休眠时间需维持不变
B45: 4.8 | C45: 1.变更字号为小(Small)、适中(Normal)、大(Large)、最大(Huge)并观察设定的选项、网页、iFileManager程序、点开右下角状态栏观察文字是否立即依比例放大缩小或有覆盖裁切等问题 2系统休眠后唤醒确认字号是否维持不变 3.系统关机后重启确认字号是否维持不变 | D45: 1.出现字号设定,默认值为Normal(适中)或Large(大)都可以 2.文字和图片显示正常不可被裁切 3.变更大小后返回上一级，并回到桌面.系统显示字型需依设定立即放大或缩小且不可覆盖或裁切 4.休眠唤醒字号需维持不变 5.关机重启字号需维持不变
...

Sheet Peripheral
B1: NO. | C1: 测试项目 | D1: 判断标准 | E1: 结果 | F1: 备注
B2: Touch Pen Vender：
B3: Touch Pen FW：
B4: Plate cover Vender：
B5: 1.Touch pen function（如配套外围设备中有触控笔则测试，没有请在结果栏打上N/A）
B6: 1.1 | C6: 单击 | D6: 单击app或功能icon可选中或打开
B7: 1.2 | C7: 长按 | D7: 1.在app icon上长按出现编辑菜单 2.在桌面空白处长按出现编辑菜单
B8: 1.3 | C8: 拖动 | D8: 1.选中图标并拖动可将图标拖动
B9: 1.4 | C9: 画线 | D9: 1.下载画图apk，使用pen在可活动区域内不间断的画圈至满屏，不可出现跳线、断线或偏移
B10: 2.Plate cover（如配套外围设备中有平板保护套则测试，没有请在结果栏打上N/A）
B11: 2.1 | C11: 平板保护套可轻松套上或取下 | D11: 1.不能与按钮、接口出现干涉 2.可以轻松套上或取下，并且不容易脱落
B12: 2.2 | C12: 如果保护套支持放置触控笔，笔可以轻松放入或取下 | D12: 1.不能与按钮、接口出现干涉 2.可以轻松放入或取下，并且不容易脱落
B13: 2.3 | C13: 如果保护套支持站立功能，平板可以站立 | D13: 平板可以站立，不晃动
B14: 2.4 | C14: 如果保护套支持息屏功能，功能正常 | D14: 1.盒盖息屏 2.开盖唤醒
B15: 3.插针（如配套外围设备中有插针则测试，没有请在结果栏打上N/A）
B16: 3.1 | C16: 插针可以使空卡槽弹出 | D16: 插针可以轻松使空卡槽弹出
B17: 3.2 | C17: 插针可以使搭载TF卡或SIM卡的卡槽弹出 | D17: 插针可以轻松使搭载TF卡或SIM卡的卡槽弹出
B19: 所有外围配套设备视图 | F19: =COUNTA(E6:E9,E11:E14,E16:E17)/COUNTA(D6:D9,D11:D14,D16:D17) -> 0

Sheet BatteryLife
B1: NO. | C1: 测试项目 | D1: 判断标准 | E1: 结果 | F1: 备注
B2: 1.充电时间测试
B3: 1.1 | C3: 关机充电 | D3: 接标配适配器，在关机状态下充电，记录充满电的所需时间。
B4: 1.2 | C4: 待机充电 | D4: 接标配适配器，待机状态下充电（打开电池曲线APK），记录充满电的所需时间。
B5: 1.3 | C5: 开机播放时间充电 | D5: 保持默认音量及亮度，接标配适配器，开机播放视频工作状态下充电（打开电池曲线APK），记录充满电的所需时间，确认充电曲线平缓无异常
B6: 2.放电时间测试
B7: 2.1 | C7: 高性能放电 | D7: 将电池电量充到100%，亮度音量最大，WIFI、蓝牙打开，播放本地”那些年.mp4，1080P视频文件，（打开电池曲线APK）播放到没电自动关机，记录放电时间，及放电曲线。
B8: 2.2 | C8: 默认性能放电 | D8: 将电池电量充到100%，默认亮度，默认音量，WIFI、蓝牙打开，播放本地”那些年.mp4，1080P视频文件，（打开电池曲线APK）播放到没电自动关机，记录放电时间。
B9: 2.3 | C9: 高性能播放网络视频放电 | D9: 将电池电量充到100%，亮度音量最大，WIFI、蓝牙打开，播放网络腾讯APP电视剧视频文件，（打开电池曲线APK）播放到没电自动关机，记录放电时间。
B10: 2.4 | C10: 低性能放电 | D10: 将电池电量充到100%，WIFI、蓝牙关闭，待机状态放置24小时（打开电池曲线APK），检查电量
B11: 2.5 | C11: 屏幕常亮放电 | D11: 将电池电量充到100%，默认亮度，默认音量，WIFI、蓝牙打开，设置永不息屏，（打开电池曲线APK）放电至自动关机，记录放电时间
B12: 3.充电干扰测试
B13: 3.1 | C13: 电源适配器 兼容TP测试 | D13: 连接适配器，单点、多点触摸TP无报点、抖动等异常现象，单点、多点画线，无乱报点、断线等异常现象。（110/220V下测试）
B14: 3.2 | C14: 电源适配器 充电测试 | D14: 1.插上适配器，进行充电； 2.充电标识显示正常；充电时间符合理论要求。
B15: 3.3 | C15: 电源适配器 干扰测试 | D15: 在插上适配器状态下，进行Wifi连接、进出照相机、播放音视频等操作；不能出现画面、声音异常等现象。
D16: 在相机预览界面，拔插适配器，在录像过程中，拔插适配器；照相机功能及显示画面不能受影响。
B17: 3.4 | C17: 低电量测试 播放音乐 | D17: 播放音乐，音频输出正常，没有断续、失真等问题
B18: 3.5 | C18: 低电量测试 播放视频 | D18: 1.播放视频 2.插入耳机 3.音视频均输出正常，没有断续、失真等问题
B19: 3.6 | C19: 低电量测试 连接蓝牙 | D19: 1.可以配对成功 2.可以正常传输文件 3.可以使用蓝牙音响播放音频
B20: 3.7 | C20: 低电量测试 连接wifi | D20: 1.可以正常连接wifi 2.关闭开启wifi可以自动重连
B21: 3.8 | C21: 低电量测试 在线浏览网页 | D21: 可以正常浏览网页
B22: 3.9 | C22: 低电量测试 在线播放音乐 | D22: 音频输出正常，没有断续、失真等问题
B23: 3.10 | C23: 低电量测试 在线播放视频 | D23: 音视频均输出正常，没有断续、失真等问题
B24: 3.11 | C24: 电量耗尽充电可以立即开机 | D24: 1.低电量自动关机（自动关机电量按Spec） 2.插入充电器 3.长按电源键开机，可以立即开机
F26: =COUNTA(E13:E24,E7:E10,E3:E5)/COUNTA(D13:D24,D7:D10,D3:D5) -> 0
B27: 待机充电曲线，播放视频充电曲线视图
B30: 高性能放电曲线，默认性能放电曲线，屏幕常亮放电曲线视图

Sheet Software
B1: NO. | C1: 测试项目 | D1: 判断标准 | E1: 结果 | F1: 备注
B2: Software name：
B3: Software version：
B4: 1.航智云软件
B5: 1.1 | C5: 根据软件厂商提供的测试规范进行测试 | D5: 按照软件厂商提供的测试规范进行测试
F6: =COUNTA(E5)/COUNTA(D5) -> 0
